Traceback (most recent call last):
  File "/Users/kvarada/opt/miniconda3/envs/cpsc330/lib/python3.9/site-packages/jupyter_cache/executors/utils.py", line 51, in single_nb_execution
    executenb(
  File "/Users/kvarada/opt/miniconda3/envs/cpsc330/lib/python3.9/site-packages/nbclient/client.py", line 1117, in execute
    return NotebookClient(nb=nb, resources=resources, km=km, **kwargs).execute()
  File "/Users/kvarada/opt/miniconda3/envs/cpsc330/lib/python3.9/site-packages/nbclient/util.py", line 78, in wrapped
    return just_run(coro(*args, **kwargs))
  File "/Users/kvarada/opt/miniconda3/envs/cpsc330/lib/python3.9/site-packages/nbclient/util.py", line 57, in just_run
    return loop.run_until_complete(coro)
  File "/Users/kvarada/opt/miniconda3/envs/cpsc330/lib/python3.9/asyncio/base_events.py", line 642, in run_until_complete
    return future.result()
  File "/Users/kvarada/opt/miniconda3/envs/cpsc330/lib/python3.9/site-packages/nbclient/client.py", line 558, in async_execute
    await self.async_execute_cell(
  File "/Users/kvarada/opt/miniconda3/envs/cpsc330/lib/python3.9/site-packages/nbclient/client.py", line 862, in async_execute_cell
    self._check_raise_for_error(cell, exec_reply)
  File "/Users/kvarada/opt/miniconda3/envs/cpsc330/lib/python3.9/site-packages/nbclient/client.py", line 765, in _check_raise_for_error
    raise CellExecutionError.from_cell_and_msg(cell, exec_reply_content)
nbclient.exceptions.CellExecutionError: An error occurred while executing the following cell:
------------------
train_df, test_df = train_test_split(adult_df_large, test_size=0.99, random_state=42)
------------------

[0;31m---------------------------------------------------------------------------[0m
[0;31mNameError[0m                                 Traceback (most recent call last)
[0;32m/var/folders/80/kr9rkqfj4w78h49djkz8yy9r0000gp/T/ipykernel_68126/3730860457.py[0m in [0;36m<module>[0;34m[0m
[0;32m----> 1[0;31m [0mtrain_df[0m[0;34m,[0m [0mtest_df[0m [0;34m=[0m [0mtrain_test_split[0m[0;34m([0m[0madult_df_large[0m[0;34m,[0m [0mtest_size[0m[0;34m=[0m[0;36m0.99[0m[0;34m,[0m [0mrandom_state[0m[0;34m=[0m[0;36m42[0m[0;34m)[0m[0;34m[0m[0;34m[0m[0m
[0m
[0;31mNameError[0m: name 'adult_df_large' is not defined
NameError: name 'adult_df_large' is not defined

