Traceback (most recent call last):
  File "/Users/kvarada/opt/miniconda3/envs/cpsc330/lib/python3.9/site-packages/jupyter_cache/executors/utils.py", line 51, in single_nb_execution
    executenb(
  File "/Users/kvarada/opt/miniconda3/envs/cpsc330/lib/python3.9/site-packages/nbclient/client.py", line 1117, in execute
    return NotebookClient(nb=nb, resources=resources, km=km, **kwargs).execute()
  File "/Users/kvarada/opt/miniconda3/envs/cpsc330/lib/python3.9/site-packages/nbclient/util.py", line 78, in wrapped
    return just_run(coro(*args, **kwargs))
  File "/Users/kvarada/opt/miniconda3/envs/cpsc330/lib/python3.9/site-packages/nbclient/util.py", line 57, in just_run
    return loop.run_until_complete(coro)
  File "/Users/kvarada/opt/miniconda3/envs/cpsc330/lib/python3.9/asyncio/base_events.py", line 642, in run_until_complete
    return future.result()
  File "/Users/kvarada/opt/miniconda3/envs/cpsc330/lib/python3.9/site-packages/nbclient/client.py", line 558, in async_execute
    await self.async_execute_cell(
  File "/Users/kvarada/opt/miniconda3/envs/cpsc330/lib/python3.9/site-packages/nbclient/client.py", line 862, in async_execute_cell
    self._check_raise_for_error(cell, exec_reply)
  File "/Users/kvarada/opt/miniconda3/envs/cpsc330/lib/python3.9/site-packages/nbclient/client.py", line 765, in _check_raise_for_error
    raise CellExecutionError.from_cell_and_msg(cell, exec_reply_content)
nbclient.exceptions.CellExecutionError: An error occurred while executing the following cell:
------------------
from tensorflow.keras.datasets import mnist
from tensorflow.keras.layers import Dense, Dropout, Flatten, Activation, Conv2D, MaxPooling2D, GlobalAveragePooling2D
from tensorflow.keras.models import Sequential, Model, load_model
from tensorflow.keras.preprocessing.image import img_to_array, load_img
from tensorflow.keras import utils
from tensorflow.keras.applications.inception_v3 import InceptionV3
from tensorflow.keras.applications.resnet50 import ResNet50, preprocess_input, decode_predictions

from skimage.segmentation import mark_boundaries
------------------

[0;31m---------------------------------------------------------------------------[0m
[0;31mModuleNotFoundError[0m                       Traceback (most recent call last)
[0;32m/var/folders/80/kr9rkqfj4w78h49djkz8yy9r0000gp/T/ipykernel_36797/4048135545.py[0m in [0;36m<module>[0;34m[0m
[0;32m----> 1[0;31m [0;32mfrom[0m [0mtensorflow[0m[0;34m.[0m[0mkeras[0m[0;34m.[0m[0mdatasets[0m [0;32mimport[0m [0mmnist[0m[0;34m[0m[0;34m[0m[0m
[0m[1;32m      2[0m [0;32mfrom[0m [0mtensorflow[0m[0;34m.[0m[0mkeras[0m[0;34m.[0m[0mlayers[0m [0;32mimport[0m [0mDense[0m[0;34m,[0m [0mDropout[0m[0;34m,[0m [0mFlatten[0m[0;34m,[0m [0mActivation[0m[0;34m,[0m [0mConv2D[0m[0;34m,[0m [0mMaxPooling2D[0m[0;34m,[0m [0mGlobalAveragePooling2D[0m[0;34m[0m[0;34m[0m[0m
[1;32m      3[0m [0;32mfrom[0m [0mtensorflow[0m[0;34m.[0m[0mkeras[0m[0;34m.[0m[0mmodels[0m [0;32mimport[0m [0mSequential[0m[0;34m,[0m [0mModel[0m[0;34m,[0m [0mload_model[0m[0;34m[0m[0;34m[0m[0m
[1;32m      4[0m [0;32mfrom[0m [0mtensorflow[0m[0;34m.[0m[0mkeras[0m[0;34m.[0m[0mpreprocessing[0m[0;34m.[0m[0mimage[0m [0;32mimport[0m [0mimg_to_array[0m[0;34m,[0m [0mload_img[0m[0;34m[0m[0;34m[0m[0m
[1;32m      5[0m [0;32mfrom[0m [0mtensorflow[0m[0;34m.[0m[0mkeras[0m [0;32mimport[0m [0mutils[0m[0;34m[0m[0;34m[0m[0m

[0;31mModuleNotFoundError[0m: No module named 'tensorflow'
ModuleNotFoundError: No module named 'tensorflow'

